2021-02-27 19:59:30,180 INFO: Microblog startup [in /Users/ivankhokhlov/Flask/microblog/app/__init__.py:49]
2021-02-27 19:59:38,956 ERROR: Exception on /edit_profile [POST] [in /Users/ivankhokhlov/Flask/microblog/venv/lib/python3.9/site-packages/flask/app.py:1891]
Traceback (most recent call last):
  File "/Users/ivankhokhlov/Flask/microblog/venv/lib/python3.9/site-packages/sqlalchemy/engine/base.py", line 1276, in _execute_context
    self.dialect.do_execute(
  File "/Users/ivankhokhlov/Flask/microblog/venv/lib/python3.9/site-packages/sqlalchemy/engine/default.py", line 609, in do_execute
    cursor.execute(statement, parameters)
sqlite3.IntegrityError: UNIQUE constraint failed: user.username

The above exception was the direct cause of the following exception:

Traceback (most recent call last):
  File "/Users/ivankhokhlov/Flask/microblog/venv/lib/python3.9/site-packages/flask/app.py", line 2447, in wsgi_app
    response = self.full_dispatch_request()
  File "/Users/ivankhokhlov/Flask/microblog/venv/lib/python3.9/site-packages/flask/app.py", line 1952, in full_dispatch_request
    rv = self.handle_user_exception(e)
  File "/Users/ivankhokhlov/Flask/microblog/venv/lib/python3.9/site-packages/flask/app.py", line 1821, in handle_user_exception
    reraise(exc_type, exc_value, tb)
  File "/Users/ivankhokhlov/Flask/microblog/venv/lib/python3.9/site-packages/flask/_compat.py", line 39, in reraise
    raise value
  File "/Users/ivankhokhlov/Flask/microblog/venv/lib/python3.9/site-packages/flask/app.py", line 1950, in full_dispatch_request
    rv = self.dispatch_request()
  File "/Users/ivankhokhlov/Flask/microblog/venv/lib/python3.9/site-packages/flask/app.py", line 1936, in dispatch_request
    return self.view_functions[rule.endpoint](**req.view_args)
  File "/Users/ivankhokhlov/Flask/microblog/venv/lib/python3.9/site-packages/flask_login/utils.py", line 272, in decorated_view
    return func(*args, **kwargs)
  File "/Users/ivankhokhlov/Flask/microblog/app/routes.py", line 103, in edit_profile
    db.session.commit()
  File "/Users/ivankhokhlov/Flask/microblog/venv/lib/python3.9/site-packages/sqlalchemy/orm/scoping.py", line 163, in do
    return getattr(self.registry(), name)(*args, **kwargs)
  File "/Users/ivankhokhlov/Flask/microblog/venv/lib/python3.9/site-packages/sqlalchemy/orm/session.py", line 1046, in commit
    self.transaction.commit()
  File "/Users/ivankhokhlov/Flask/microblog/venv/lib/python3.9/site-packages/sqlalchemy/orm/session.py", line 504, in commit
    self._prepare_impl()
  File "/Users/ivankhokhlov/Flask/microblog/venv/lib/python3.9/site-packages/sqlalchemy/orm/session.py", line 483, in _prepare_impl
    self.session.flush()
  File "/Users/ivankhokhlov/Flask/microblog/venv/lib/python3.9/site-packages/sqlalchemy/orm/session.py", line 2540, in flush
    self._flush(objects)
  File "/Users/ivankhokhlov/Flask/microblog/venv/lib/python3.9/site-packages/sqlalchemy/orm/session.py", line 2682, in _flush
    transaction.rollback(_capture_exception=True)
  File "/Users/ivankhokhlov/Flask/microblog/venv/lib/python3.9/site-packages/sqlalchemy/util/langhelpers.py", line 68, in __exit__
    compat.raise_(
  File "/Users/ivankhokhlov/Flask/microblog/venv/lib/python3.9/site-packages/sqlalchemy/util/compat.py", line 182, in raise_
    raise exception
  File "/Users/ivankhokhlov/Flask/microblog/venv/lib/python3.9/site-packages/sqlalchemy/orm/session.py", line 2642, in _flush
    flush_context.execute()
  File "/Users/ivankhokhlov/Flask/microblog/venv/lib/python3.9/site-packages/sqlalchemy/orm/unitofwork.py", line 422, in execute
    rec.execute(self)
  File "/Users/ivankhokhlov/Flask/microblog/venv/lib/python3.9/site-packages/sqlalchemy/orm/unitofwork.py", line 586, in execute
    persistence.save_obj(
  File "/Users/ivankhokhlov/Flask/microblog/venv/lib/python3.9/site-packages/sqlalchemy/orm/persistence.py", line 230, in save_obj
    _emit_update_statements(
  File "/Users/ivankhokhlov/Flask/microblog/venv/lib/python3.9/site-packages/sqlalchemy/orm/persistence.py", line 994, in _emit_update_statements
    c = cached_connections[connection].execute(
  File "/Users/ivankhokhlov/Flask/microblog/venv/lib/python3.9/site-packages/sqlalchemy/engine/base.py", line 1011, in execute
    return meth(self, multiparams, params)
  File "/Users/ivankhokhlov/Flask/microblog/venv/lib/python3.9/site-packages/sqlalchemy/sql/elements.py", line 298, in _execute_on_connection
    return connection._execute_clauseelement(self, multiparams, params)
  File "/Users/ivankhokhlov/Flask/microblog/venv/lib/python3.9/site-packages/sqlalchemy/engine/base.py", line 1124, in _execute_clauseelement
    ret = self._execute_context(
  File "/Users/ivankhokhlov/Flask/microblog/venv/lib/python3.9/site-packages/sqlalchemy/engine/base.py", line 1316, in _execute_context
    self._handle_dbapi_exception(
  File "/Users/ivankhokhlov/Flask/microblog/venv/lib/python3.9/site-packages/sqlalchemy/engine/base.py", line 1510, in _handle_dbapi_exception
    util.raise_(
  File "/Users/ivankhokhlov/Flask/microblog/venv/lib/python3.9/site-packages/sqlalchemy/util/compat.py", line 182, in raise_
    raise exception
  File "/Users/ivankhokhlov/Flask/microblog/venv/lib/python3.9/site-packages/sqlalchemy/engine/base.py", line 1276, in _execute_context
    self.dialect.do_execute(
  File "/Users/ivankhokhlov/Flask/microblog/venv/lib/python3.9/site-packages/sqlalchemy/engine/default.py", line 609, in do_execute
    cursor.execute(statement, parameters)
sqlalchemy.exc.IntegrityError: (sqlite3.IntegrityError) UNIQUE constraint failed: user.username
[SQL: UPDATE user SET username=?, about_me=? WHERE user.id = ?]
[parameters: ('ivan', '', 9)]
(Background on this error at: http://sqlalche.me/e/13/gkpj)
2021-03-02 09:06:29,238 INFO: Microblog startup [in /Users/ivankhokhlov/Flask/microblog/app/__init__.py:51]
2021-03-02 09:43:19,412 INFO: Microblog startup [in /Users/ivankhokhlov/Flask/microblog/app/__init__.py:51]
2021-03-02 09:44:42,341 ERROR: Exception on /reset_password_request [POST] [in /Users/ivankhokhlov/Flask/microblog/venv/lib/python3.9/site-packages/flask/app.py:1891]
Traceback (most recent call last):
  File "/Users/ivankhokhlov/Flask/microblog/venv/lib/python3.9/site-packages/flask_mail.py", line 492, in send
    message.send(connection)
  File "/Users/ivankhokhlov/Flask/microblog/venv/lib/python3.9/site-packages/flask_mail.py", line 427, in send
    connection.send(self)
  File "/Users/ivankhokhlov/Flask/microblog/venv/lib/python3.9/site-packages/flask_mail.py", line 188, in send
    self.host.sendmail(sanitize_address(envelope_from or message.sender),
  File "/Library/Frameworks/Python.framework/Versions/3.9/lib/python3.9/smtplib.py", line 856, in sendmail
    self.ehlo_or_helo_if_needed()
  File "/Library/Frameworks/Python.framework/Versions/3.9/lib/python3.9/smtplib.py", line 604, in ehlo_or_helo_if_needed
    if not (200 <= self.ehlo()[0] <= 299):
  File "/Library/Frameworks/Python.framework/Versions/3.9/lib/python3.9/smtplib.py", line 444, in ehlo
    self.putcmd(self.ehlo_msg, name or self.local_hostname)
  File "/Library/Frameworks/Python.framework/Versions/3.9/lib/python3.9/smtplib.py", line 371, in putcmd
    self.send(str)
  File "/Library/Frameworks/Python.framework/Versions/3.9/lib/python3.9/smtplib.py", line 363, in send
    raise SMTPServerDisconnected('please run connect() first')
smtplib.SMTPServerDisconnected: please run connect() first

During handling of the above exception, another exception occurred:

Traceback (most recent call last):
  File "/Users/ivankhokhlov/Flask/microblog/venv/lib/python3.9/site-packages/flask/app.py", line 2447, in wsgi_app
    response = self.full_dispatch_request()
  File "/Users/ivankhokhlov/Flask/microblog/venv/lib/python3.9/site-packages/flask/app.py", line 1952, in full_dispatch_request
    rv = self.handle_user_exception(e)
  File "/Users/ivankhokhlov/Flask/microblog/venv/lib/python3.9/site-packages/flask/app.py", line 1821, in handle_user_exception
    reraise(exc_type, exc_value, tb)
  File "/Users/ivankhokhlov/Flask/microblog/venv/lib/python3.9/site-packages/flask/_compat.py", line 39, in reraise
    raise value
  File "/Users/ivankhokhlov/Flask/microblog/venv/lib/python3.9/site-packages/flask/app.py", line 1950, in full_dispatch_request
    rv = self.dispatch_request()
  File "/Users/ivankhokhlov/Flask/microblog/venv/lib/python3.9/site-packages/flask/app.py", line 1936, in dispatch_request
    return self.view_functions[rule.endpoint](**req.view_args)
  File "/Users/ivankhokhlov/Flask/microblog/app/routes.py", line 181, in reset_password_request
    send_password_reset_email(user)
  File "/Users/ivankhokhlov/Flask/microblog/app/email.py", line 13, in send_password_reset_email
    send_email('[Microblog] Reset Your Password',
  File "/Users/ivankhokhlov/Flask/microblog/app/email.py", line 9, in send_email
    mail.send(msg)
  File "/Users/ivankhokhlov/Flask/microblog/venv/lib/python3.9/site-packages/flask_mail.py", line 492, in send
    message.send(connection)
  File "/Users/ivankhokhlov/Flask/microblog/venv/lib/python3.9/site-packages/flask_mail.py", line 152, in __exit__
    self.host.quit()
  File "/Library/Frameworks/Python.framework/Versions/3.9/lib/python3.9/smtplib.py", line 988, in quit
    res = self.docmd("quit")
  File "/Library/Frameworks/Python.framework/Versions/3.9/lib/python3.9/smtplib.py", line 424, in docmd
    self.putcmd(cmd, args)
  File "/Library/Frameworks/Python.framework/Versions/3.9/lib/python3.9/smtplib.py", line 371, in putcmd
    self.send(str)
  File "/Library/Frameworks/Python.framework/Versions/3.9/lib/python3.9/smtplib.py", line 363, in send
    raise SMTPServerDisconnected('please run connect() first')
smtplib.SMTPServerDisconnected: please run connect() first
