2021-03-02 21:24:33,412 ERROR: Exception on /reset_password_request [POST] [in /Users/ivankhokhlov/Flask/microblog/venv/lib/python3.9/site-packages/flask/app.py:1891]
Traceback (most recent call last):
  File "/Users/ivankhokhlov/Flask/microblog/venv/lib/python3.9/site-packages/flask/app.py", line 2447, in wsgi_app
    response = self.full_dispatch_request()
  File "/Users/ivankhokhlov/Flask/microblog/venv/lib/python3.9/site-packages/flask/app.py", line 1952, in full_dispatch_request
    rv = self.handle_user_exception(e)
  File "/Users/ivankhokhlov/Flask/microblog/venv/lib/python3.9/site-packages/flask/app.py", line 1821, in handle_user_exception
    reraise(exc_type, exc_value, tb)
  File "/Users/ivankhokhlov/Flask/microblog/venv/lib/python3.9/site-packages/flask/_compat.py", line 39, in reraise
    raise value
  File "/Users/ivankhokhlov/Flask/microblog/venv/lib/python3.9/site-packages/flask/app.py", line 1950, in full_dispatch_request
    rv = self.dispatch_request()
  File "/Users/ivankhokhlov/Flask/microblog/venv/lib/python3.9/site-packages/flask/app.py", line 1936, in dispatch_request
    return self.view_functions[rule.endpoint](**req.view_args)
  File "/Users/ivankhokhlov/Flask/microblog/app/routes.py", line 181, in reset_password_request
    send_password_reset_email(user)
  File "/Users/ivankhokhlov/Flask/microblog/app/email.py", line 13, in send_password_reset_email
    send_email('[Microblog] Reset Your Password',
  File "/Users/ivankhokhlov/Flask/microblog/app/email.py", line 9, in send_email
    mail.send(msg)
  File "/Users/ivankhokhlov/Flask/microblog/venv/lib/python3.9/site-packages/flask_mail.py", line 491, in send
    with self.connect() as connection:
  File "/Users/ivankhokhlov/Flask/microblog/venv/lib/python3.9/site-packages/flask_mail.py", line 144, in __enter__
    self.host = self.configure_host()
  File "/Users/ivankhokhlov/Flask/microblog/venv/lib/python3.9/site-packages/flask_mail.py", line 158, in configure_host
    host = smtplib.SMTP(self.mail.server, self.mail.port)
  File "/Library/Frameworks/Python.framework/Versions/3.9/lib/python3.9/smtplib.py", line 253, in __init__
    (code, msg) = self.connect(host, port)
  File "/Library/Frameworks/Python.framework/Versions/3.9/lib/python3.9/smtplib.py", line 339, in connect
    self.sock = self._get_socket(host, port, self.timeout)
  File "/Library/Frameworks/Python.framework/Versions/3.9/lib/python3.9/smtplib.py", line 310, in _get_socket
    return socket.create_connection((host, port), timeout,
  File "/Library/Frameworks/Python.framework/Versions/3.9/lib/python3.9/socket.py", line 843, in create_connection
    raise err
  File "/Library/Frameworks/Python.framework/Versions/3.9/lib/python3.9/socket.py", line 831, in create_connection
    sock.connect(sa)
ConnectionRefusedError: [Errno 61] Connection refused
2021-03-02 21:40:59,325 INFO: Microblog startup [in /Users/ivankhokhlov/Flask/microblog/app/__init__.py:51]
2021-03-02 21:41:45,683 ERROR: Exception on /reset_password_request [POST] [in /Users/ivankhokhlov/Flask/microblog/venv/lib/python3.9/site-packages/flask/app.py:1891]
Traceback (most recent call last):
  File "/Users/ivankhokhlov/Flask/microblog/venv/lib/python3.9/site-packages/flask/app.py", line 2447, in wsgi_app
    response = self.full_dispatch_request()
  File "/Users/ivankhokhlov/Flask/microblog/venv/lib/python3.9/site-packages/flask/app.py", line 1952, in full_dispatch_request
    rv = self.handle_user_exception(e)
  File "/Users/ivankhokhlov/Flask/microblog/venv/lib/python3.9/site-packages/flask/app.py", line 1821, in handle_user_exception
    reraise(exc_type, exc_value, tb)
  File "/Users/ivankhokhlov/Flask/microblog/venv/lib/python3.9/site-packages/flask/_compat.py", line 39, in reraise
    raise value
  File "/Users/ivankhokhlov/Flask/microblog/venv/lib/python3.9/site-packages/flask/app.py", line 1950, in full_dispatch_request
    rv = self.dispatch_request()
  File "/Users/ivankhokhlov/Flask/microblog/venv/lib/python3.9/site-packages/flask/app.py", line 1936, in dispatch_request
    return self.view_functions[rule.endpoint](**req.view_args)
  File "/Users/ivankhokhlov/Flask/microblog/app/routes.py", line 181, in reset_password_request
    send_password_reset_email(user)
  File "/Users/ivankhokhlov/Flask/microblog/app/email.py", line 13, in send_password_reset_email
    send_email('[Microblog] Reset Your Password',
  File "/Users/ivankhokhlov/Flask/microblog/app/email.py", line 9, in send_email
    mail.send(msg)
  File "/Users/ivankhokhlov/Flask/microblog/venv/lib/python3.9/site-packages/flask_mail.py", line 491, in send
    with self.connect() as connection:
  File "/Users/ivankhokhlov/Flask/microblog/venv/lib/python3.9/site-packages/flask_mail.py", line 144, in __enter__
    self.host = self.configure_host()
  File "/Users/ivankhokhlov/Flask/microblog/venv/lib/python3.9/site-packages/flask_mail.py", line 165, in configure_host
    host.login(self.mail.username, self.mail.password)
  File "/Library/Frameworks/Python.framework/Versions/3.9/lib/python3.9/smtplib.py", line 723, in login
    (code, resp) = self.auth(
  File "/Library/Frameworks/Python.framework/Versions/3.9/lib/python3.9/smtplib.py", line 635, in auth
    (code, resp) = self.docmd("AUTH", mechanism + " " + response)
  File "/Library/Frameworks/Python.framework/Versions/3.9/lib/python3.9/smtplib.py", line 425, in docmd
    return self.getreply()
  File "/Library/Frameworks/Python.framework/Versions/3.9/lib/python3.9/smtplib.py", line 398, in getreply
    raise SMTPServerDisconnected("Connection unexpectedly closed")
smtplib.SMTPServerDisconnected: Connection unexpectedly closed
2021-03-02 21:43:29,198 INFO: Microblog startup [in /Users/ivankhokhlov/Flask/microblog/app/__init__.py:51]
2021-03-02 21:43:43,859 ERROR: Exception on /reset_password_request [POST] [in /Users/ivankhokhlov/Flask/microblog/venv/lib/python3.9/site-packages/flask/app.py:1891]
Traceback (most recent call last):
  File "/Users/ivankhokhlov/Flask/microblog/venv/lib/python3.9/site-packages/flask/app.py", line 2447, in wsgi_app
    response = self.full_dispatch_request()
  File "/Users/ivankhokhlov/Flask/microblog/venv/lib/python3.9/site-packages/flask/app.py", line 1952, in full_dispatch_request
    rv = self.handle_user_exception(e)
  File "/Users/ivankhokhlov/Flask/microblog/venv/lib/python3.9/site-packages/flask/app.py", line 1821, in handle_user_exception
    reraise(exc_type, exc_value, tb)
  File "/Users/ivankhokhlov/Flask/microblog/venv/lib/python3.9/site-packages/flask/_compat.py", line 39, in reraise
    raise value
  File "/Users/ivankhokhlov/Flask/microblog/venv/lib/python3.9/site-packages/flask/app.py", line 1950, in full_dispatch_request
    rv = self.dispatch_request()
  File "/Users/ivankhokhlov/Flask/microblog/venv/lib/python3.9/site-packages/flask/app.py", line 1936, in dispatch_request
    return self.view_functions[rule.endpoint](**req.view_args)
  File "/Users/ivankhokhlov/Flask/microblog/app/routes.py", line 181, in reset_password_request
    send_password_reset_email(user)
  File "/Users/ivankhokhlov/Flask/microblog/app/email.py", line 13, in send_password_reset_email
    send_email('[Microblog] Reset Your Password',
  File "/Users/ivankhokhlov/Flask/microblog/app/email.py", line 9, in send_email
    mail.send(msg)
  File "/Users/ivankhokhlov/Flask/microblog/venv/lib/python3.9/site-packages/flask_mail.py", line 491, in send
    with self.connect() as connection:
  File "/Users/ivankhokhlov/Flask/microblog/venv/lib/python3.9/site-packages/flask_mail.py", line 144, in __enter__
    self.host = self.configure_host()
  File "/Users/ivankhokhlov/Flask/microblog/venv/lib/python3.9/site-packages/flask_mail.py", line 165, in configure_host
    host.login(self.mail.username, self.mail.password)
  File "/Library/Frameworks/Python.framework/Versions/3.9/lib/python3.9/smtplib.py", line 723, in login
    (code, resp) = self.auth(
  File "/Library/Frameworks/Python.framework/Versions/3.9/lib/python3.9/smtplib.py", line 635, in auth
    (code, resp) = self.docmd("AUTH", mechanism + " " + response)
  File "/Library/Frameworks/Python.framework/Versions/3.9/lib/python3.9/smtplib.py", line 425, in docmd
    return self.getreply()
  File "/Library/Frameworks/Python.framework/Versions/3.9/lib/python3.9/smtplib.py", line 398, in getreply
    raise SMTPServerDisconnected("Connection unexpectedly closed")
smtplib.SMTPServerDisconnected: Connection unexpectedly closed
2021-03-02 21:44:43,100 INFO: Microblog startup [in /Users/ivankhokhlov/Flask/microblog/app/__init__.py:51]
